IssueComment {issueCommentUpdatedAt = GithubDate {fromGithubDate = 2013-03-27 15:18:11 UTC}, issueCommentUser = GithubUser {githubOwnerAvatarUrl = "https://secure.gravatar.com/avatar/6a424256589825f609fd3477144355a0?d=https://a248.e.akamai.net/assets.github.com%2Fimages%2Fgravatars%2Fgravatar-user-420.png", githubOwnerLogin = "yarikoptic", githubOwnerUrl = "https://api.github.com/users/yarikoptic", githubOwnerId = 39889, githubOwnerGravatarId = "6a424256589825f609fd3477144355a0"}, issueCommentUrl = "https://api.github.com/repos/fail2ban/fail2ban/issues/comments/15529478", issueCommentCreatedAt = GithubDate {fromGithubDate = 2013-03-27 15:18:11 UTC}, issueCommentBody = "grr -- empire strikes back!  https://travis-ci.org/fail2ban/fail2ban/jobs/5841682\r\n```\r\nFAIL: test_move_file (testcases.filtertestcase.MonitorFailures<FilterPyinotify>(/tmp/monitorfailurescgvEDTfail2ban))\r\n\r\n----------------------------------------------------------------------\r\n\r\nTraceback (most recent call last):\r\n\r\nFile \"/home/travis/build/fail2ban/fail2ban/testcases/filtertestcase.py\", line 447, in test_move_file\r\n\r\nself.assertEqual(self.filter.failManager.getFailTotal(), 3)\r\n\r\nAssertionError: 4 != 3\r\n```\r\n\r\nSo even though it is better now -- it still needs more fix up for the ultimate reliability -- reopening", issueCommentId = 15529478}