Issue {issueClosedAt = Nothing, issueUpdatedAt = GithubDate {fromGithubDate = 2013-03-15 01:14:50 UTC}, issueHtmlUrl = "https://github.com/fail2ban/fail2ban/issues/141", issueClosedBy = Nothing, issueLabels = [], issueNumber = 141, issueAssignee = Nothing, issueUser = GithubUser {githubOwnerAvatarUrl = "https://secure.gravatar.com/avatar/6287123ea9befdb4f2540a1efd969011?d=https://a248.e.akamai.net/assets.github.com%2Fimages%2Fgravatars%2Fgravatar-user-420.png", githubOwnerLogin = "bfx81", githubOwnerUrl = "https://api.github.com/users/bfx81", githubOwnerId = 1285033, githubOwnerGravatarId = "6287123ea9befdb4f2540a1efd969011"}, issueTitle = "fail2ban 0.8.8 not log to syslog", issuePullRequest = PullRequestReference {pullRequestReferenceHtmlUrl = Nothing, pullRequestReferencePatchUrl = Nothing, pullRequestReferenceDiffUrl = Nothing}, issueUrl = "https://api.github.com/repos/fail2ban/fail2ban/issues/141", issueCreatedAt = GithubDate {fromGithubDate = 2013-03-15 01:14:50 UTC}, issueBody = "- gentoo with python 2.7\r\n- \"logtarget = SYSLOG\" in fail2ban.conf\r\n- metalog as syslogger not receive nothing (even in \"everything\" filter)\r\n\r\nOther people had the same problem, (http://forums.gentoo.org/viewtopic-t-914228-view-next.html?sid=de50b16395377f98a99135755cb9e883) and we have not problem with metalog receiving logs from other software.\r\nTnx in advance for your attention (and obviously for this great tool!\r\n", issueState = "open", issueId = 12046756, issueComments = 0, issueMilestone = Nothing}